Workbook

Sheet README
A1: EMERGISIM - Anaphylaxis FSM Dataset (final)
A2: Source | B2: Cardona et al., World Allergy Organization Anaphylaxis Guidance 2020, World Allergy Organ J 13:100472. Page numbers refer to the PDF. Every value is tagged with its source; anything the paper does not give is left blank for MIMIC-IV-ED or other literature.
A3: Grade mapping | B3: Early Reaction = Table 7 grade 3, Airway Compromise = grade 4, Cardiovascular Collapse = grade 5. Checked against the rendered PDF pages 13-14 (F-07).
A5: Sheet index
A6: Verify_Flags | B6: 31 flags: 22 Resolved/Verified, 4 Partially resolved, 2 Still open (design decisions or data), 2 explicitly FSM-designer/other-dataset scope, 1 informational caution only. RCUK 2021 and EAACI 2021 PDFs read; F-26 to F-31 added; State_Actions/Transitions realigned with Bundle_Sequence (F-26); F-25 numeric modifiers resolved via Worm et al. 2018 (see Worm2018_Modifiers sheet); F-09 C-04 exemption note aligned for cardiovascular_collapse; F-18 closed with 4 new symptoms/signs (cyanosis, increased work of breathing, pale/clammy skin, tachycardia). 25 Sep 2026.
A7: WAO_Grade_Map | B7: Table 7 grades 1-5 mapped to the 4 FSM states
A8: Global_Rules | B8: Diagnostic criteria, hypotension definition, epinephrine rules, second-line drugs, observation, tryptase
A9: Epinephrine_Doses | B9: IM adrenaline dose comparison across RCUK 2021 (default), WAO 2020 and EAACI 2021 (auto-injector and healthcare-setting doses)
A10: States | B10: The 4 FSM states with WAO grade, basis, entry requirement and transitions
A11: State_Symptoms | B11: Allowed / forbidden / superseded symptoms per state by symptom_id, with modality and who can report (one row per state per symptom, 90 rows, ready for LLM prompt building)
A12: Symptom_Master | B12: One row per symptom: symptom_id, first_state, modality, applies_to. Edit here, then regenerate State_Symptoms
A13: State_Communication | B13: Consciousness and speech ability per state (collapse has conscious_hypotensive and unconscious variants)
A14: Actions | B14: Action library ANA-xxx with category, notes, source (17 actions; ANA-018 = take tryptase sample)
A15: Contraindicated | B15: C-01 to C-04, explicit vs derived, RCUK/EAACI guideline_support column, time_penalty_seconds input (FSM designer)
A16: State_Actions | B16: State x action mapping with tier, now explicit for all 17 actions in all 3 states, realigned with Bundle_Sequence (F-26)
A17: Transitions | B17: FSM transitions; timer inputs
... A35: Needle_Gauge | B35: IM needle gauge, colour code and length by age, and the injection site
A37: Legend
A38: Yellow cell, blue text | B38: INPUT cell for your team to fill (timers, time penalties, vitals) or an example input in Calculators.
A39: Grey italic row | B39: Example row in Vitals_Template showing the expected format. NOT clinical data. Delete before use.
A40: Evidence level | B40: In State_Symptoms: 'Direct' = term appears in the paper; 'Derived' = patient-language wording (see F-08).
A41: Action IDs | B41: ANA-005 is intentionally unused (IDs are stable identifiers, not a count).
A42: PS IDs | B42: Post-recovery actions (Post_Stable_Brain3) use PS-01 to PS-15. Before the Stable state they are neutral (F-19).
A43: Status values | B43: In State_Symptoms: 'allowed' = may be conveyed; 'forbidden' = first appears in a later state, never mention; 'superseded' = same organ, replaced by a more severe wording, do not mention.
A44: Modality | B44: subjective = only the patient can report it; observed = trainee sees or hears it; both = either; measured = monitor value. Derived classification (F-12).
A45: Blank vs 'not graded' | B45: 'not graded' = symptom is not in WAO Table 7 (e.g. sense of heat). Blank in patient_can_report, trainee_can_observe, criterion1_role, inherited_from_earlier_state on forbidden/superseded rows = not applicable (those columns describe allowed symptoms only). Blank in Transitions base_timer_seconds = action-triggered, no timer. Blank in a yellow input cell = still to be filled (vitals, timers, time penalties).
A47: Summary (formulas)
A48: Symptom rows | B48: =COUNTA(State_Symptoms!A2:A91) -> 90
A49: Symptoms defined | B49: =COUNTA(Symptom_Master!A2:A31) -> 30
A50: Extra facts recorded | B50: =COUNTA(Extra_Facts!A2:A33) -> 32
A51: Actions defined | B51: =COUNTA(Actions!A2:A18) -> 17
A52: State-action mappings | B52: =COUNTA(State_Actions!A2:A63) -> 62
A53: Hints defined | B53: =COUNTA(Hints!A2:A25) -> 24
A54: Contraindicated actions | B54: =COUNTA(Contraindicated!A2:A5) -> 4
A55: Input cells still blank | B55: =COUNTBLANK(Vitals_Template!D2:M5)+COUNTBLANK(Contraindicated!H2:H5)+COUNTBLANK(Transitions!F3)+COUNTBLANK(Transitions!F5)+COUNTBLANK(Transitions!F7) -> 47

Sheet Verify_Flags
A1: flag_id | B1: severity | C1: topic | D1: issue | E1: recommended_action | F1: previous_severity
A2: F-01 | B2: Resolved in dataset | C2: WAO grade labels in your FSM doc | D2: Table 7 (p.13) gives: grade 3 = mild bronchospasm and/or GI; grade 4 = severe bronchospasm and/or laryngeal edema with stridor; grade 5 = respiratory failure and/or collapse/hypotension and/or loss of consciousness. Grades 1-2 are 'Not anaphylaxis'. Your FSM doc labels Early Reaction 'Grade I-II', Airway Compromise 'Grade III' and Cardiovascular Collapse 'Grade IV', which is one grade off. UPDATE (24 Sep 2026): WAO_Grade_Map.fsm_state_v2 and States already map grade 3 -> early_reaction, grade 4 -> airway_compromise, grade 5 -> cardiovascular_collapse -- this matches the recommended action exactly. The mislabelling ('Grade I-II' / 'III' / 'IV') is only in the separate FSM design document, not in this workbook; that document is being corrected outside this file. | E2: Change the doc to Early Reaction = Grade III (also meeting Table 2 criterion 1), Airway Compromise = Grade IV, Cardiovascular Collapse = Grade V. See WAO_Grade_Map. | F2: High
A3: F-02 | B3: Open — vitals/timers dataset + FSM designer scope | C3: Values the paper does not give | D3: No HR, RR, SpO2 ranges and no time-to-deterioration figures. Paper also notes fatal/near-fatal events are rare even when untreated. UPDATE (24 Sep 2026): Confirmed out of scope for guideline sourcing -- Vitals_Template values come from MIMIC-IV-ED (a separate dataset), and Transitions timers/compression are the FSM designer's decision (same scope as F-17, F-24, F-25). | E3: Fill Vitals_Template from MIMIC-IV-ED and Transitions timers from other literature. Describe 'no action -> scenario_end' as a simulation design choice, not a WAO claim. | F3: High
A4: F-03 | B4: Resolved | C4: IV fluid dose discrepancy | D4: Text (p.15): 20 mL/kg crystalloid bolus. Fig. 4 (p.11): 1-2 L of 0.9% saline (5-10 mL/kg in first 5-10 min for an adult; 10 mL/kg for a child). UPDATE (24 Sep 2026): Superseded by F-22: Fluid_Bolus_Comparison now uses RCUK 2021 (10 mL/kg child, 500-1000 mL adult, RCUK p.31) as the workbook default, with the WAO text (20 mL/kg) and WAO Fig. 4 (5-10 mL/kg adult first bolus, 10 mL/kg child) kept as comparison rows. No WAO-only figure is used uncited. | E4: Pick one and cite it consistently. Both are in the paper. | F4: Medium
A5: F-04 | B5: Resolved | C5: Typos in the source PDF | D5: Fig. 1 footnote says '>3%' (text and Table 2 say 30%). Text on p.17 says '500 mg (0.5 mg)'. Table 6 rows for 6-12 y and teenagers/adults omit the mL figure (only the header gives 0.5 mL). UPDATE (24 Sep 2026): This is an internal WAO-paper typo, unrelated to RCUK/EAACI. Confirmed: Epinephrine_Doses already computes WAO volumes as dose / 1 mg/mL (0.15/0.3/0.5 mL all present) and Autoinjector_Notes already uses 0.5 mg. No change needed. | E5: Use 30% and 0.5 mg. Volumes in Epinephrine_Doses are computed (dose / 1 mg/mL), not copied. | F5: Medium
A6: F-05 | B6: Resolved | C6: Maximum epinephrine dose | D6: Text and Table 6: max 0.5 mg. Fig. 4: max 0.5 mg adult or 0.3 mg child. UPDATE (24 Sep 2026): Neither RCUK nor EAACI states a single flat 'maximum dose' the way WAO's text does. Both use age/weight bands instead, and in both the child band is capped below the adult dose (RCUK: 150/300 micrograms for children vs 500 for adult/>12y, p.29; EAACI: 0.15/0.3 mg for children vs at least 0.3 mg for adolescents/adults, p.364), matching WAO Fig. 4's approach (child capped at 0.3 mg) rather than a flat 0.5 mg text-only rule for all ages. This supports keeping the Calculators sheet's Fig. 4-based 0.3 mg child cap as the default. | E6: Calculators sheet caps child at 0.3 mg per Fig. 4. Change if your team prefers the text-only rule. | F6: Low
A7: F-06 | B7: Resolved | C7: Contraindicated tier is partly derived | D7: WAO lists few explicit contraindications. C-01, C-02 and C-04 are explicit; C-03 (substituting other drugs for epinephrine) is derived from statements that bronchodilators are not an alternative and antihistamines can delay epinephrine. Time-penalty size is your design parameter. UPDATE (24 Sep 2026, RCUK 2021 and EAACI 2021 read): RCUK now states all four explicitly. C-01: IV adrenaline only by experienced specialists in an appropriate setting; undiluted 1:1000 must not be given IV (RCUK pp.7, 30, 37, Appendix 3 p.57; EAACI pp.362-363). C-02: H1-antihistamines can cause hypotension when given as a rapid IV bolus (RCUK p.32). C-03: antihistamines must not be given in preference to adrenaline and their use often delays it (RCUK p.32); steroids must not be given preferentially to adrenaline (p.33); bronchodilators and nebulised adrenaline must not replace further parenteral adrenaline (pp.30, 33). C-04: fatality can occur within minutes if the patient stands, walks or sits up suddenly (RCUK pp.19, 26; EAACI p.361: avoid any abrupt change to a more upright posture). RCUK says 'within minutes' and WAO 'within seconds'; quote each source in its own wording. RCUK p.37 allows a specialist IV bolus while an infusion is being set up, so C-01 applies to non-specialist trainees. | E7: Tier is source-confirmed. C-03 can now be treated as Explicit (RCUK 2021); see Contraindicated column I. time_penalty_seconds is set by the FSM designer (F-24). Clinical expert validation remains the final step. | F7: High
A8: F-07 | B8: Verified | C8: Table 7 grade columns | D8: Checked on the rendered PDF page 13. Header 'Not anaphylaxis' spans grades 1-2 and 'ANAPHYLAXIS' spans grades 3-5. Grade 3 = mild bronchospasm and/or GI (abdominal cramps, vomiting/diarrhea), uterine cramps; grade 4 = severe bronchospasm and/or laryngeal edema with stridor; grade 5 = respiratory failure and/or collapse/hypotension and/or loss of consciousness. No 'death' grade exists. | E8: None. The header lists grade 3 under ANAPHYLAXIS while the p.17 text says only some grade 3 reactions fit the definition, which is why Early Reaction also requires Table 2 criterion 1.
A9: F-08 | B9: Resolved (note verified correct) | C9: Derived symptom wording | D9: 'Throat or tongue tightness' and 'marked shortness of breath' are patient-language renderings of laryngeal involvement (Table 2) and severe bronchospasm (Table 7 grade 4), not verbatim paper terms. Marked 'Derived' in State_Symptoms. UPDATE (24 Sep 2026): Checked against RCUK/EAACI: both use similar patient-facing language ('throat feels as if it is closing', 'sense of impending doom', RCUK pp.21-22; persistent cough, difficult/noisy breathing, EAACI Boxes 6-7 pp.369-370) without giving these as verbatim WAO terms either. The existing note (keep for dialogue, do not cite as direct WAO wording) is accurate and needs no change. | E9: Keep for natural dialogue, but do not cite them as direct WAO wording. | F9: Medium
A10: F-09 | B10: Resolved | C10: C-04 is conditional | D10: Fig. 4 warns fatality can occur within seconds if the patient stands or sits suddenly, but sitting is acceptable when there is respiratory distress (p.15). UPDATE (24 Sep 2026, RCUK 2021 and EAACI 2021 read): RCUK p.26 (section 4.4) and Fig. 6 p.25: patients must not walk or stand during acute reactions; patients with Airway and Breathing problems may prefer a semi-recumbent position; lying flat, with or without leg elevation, for low blood pressure. EAACI p.361 and Fig. 1 p.364 say the same. RCUK p.19 limits the semi-recumbent position to predominantly respiratory symptoms with no evidence of cardiovascular instability. UPDATE (25 Sep 2026): State_Actions row for C-04 in cardiovascular_collapse aligned — the 'not in respiratory distress' exemption has been removed for this state; RCUK p.19 confines that exemption to purely respiratory presentations with no cardiovascular instability. | E10: Done — condition_note for C-04 in cardiovascular_collapse (State_Actions) updated to remove the respiratory-distress exemption. | F10: Medium
A11: F-10 | B11: Resolved (see F-20, F-26) | C11: Bundle logic not specified | D11: WAO names IM epinephrine as first-line/definitive; O2, IV access and fluids are supportive. It does not say whether all listed actions are required for a transition. UPDATE (24 Sep 2026): Team decision made: not ALL, not ANY, but a per-state required set (see Bundle_Sequence and the State_Actions tiers realigned in F-26). F-10 is superseded and kept only for history. | E11: Team decision (ALL vs epinephrine-only vs ANY). Brain 3 partial credit applies either way (FSM doc, Limitation 4). | F11: Medium
A12: F-11 | B12: Partially resolved | C12: Speech ability per state is derived | D12: WAO gives loss of consciousness only for grade 5, and grade 5 is 'and/or' (collapse/hypotension can occur while conscious). 'Short phrases' for grade 4 and 'full sentences' for grade 3 are standard clinical assessment, not WAO wording. See State_Communication. UPDATE (24 Sep 2026, RCUK 2021 and EAACI 2021 read): Consciousness and collapse features are supported by RCUK pp.21-22 and Table 3 p.23 (dizziness, decreased conscious level or loss of consciousness, confusion, agitation), EAACI Fig. 1 p.364 (dizziness, fainting, confusion) and EAACI Boxes 6-7 pp.369-370 (persistent dizziness, suddenly sleepy, collapse/unconscious). Loss of consciousness is not required for grade 5, which supports the conscious_hypotensive variant. The speech-ability wording (full sentences / short phrases / single words) is not in RCUK, EAACI or WAO. | E12: Keep the speech column marked 'Derived (clinical convention)' and do not cite it to any anaphylaxis guideline. Clinical expert to confirm at final validation. | F12: Medium
A13: F-12 | B13: Still open | C13: Modality classification is derived | D13: subjective / observed / both / measured in Symptom_Master follows clinical convention (what only the patient can report vs what the trainee can see, hear or read on a monitor). It is not stated in WAO. UPDATE (24 Sep 2026, RCUK 2021 and EAACI 2021 read): Neither RCUK nor EAACI classifies symptoms as subjective / observed / both / measured. RCUK p.21 and EAACI Fig. 1 p.364 list symptoms and signs together, so they can be used to cross-check placement but not to validate the classification. | E13: Document as a design definition (symptom = reported by the patient; sign = observed or measured), not a guideline claim. Expert to spot-check. | F13: Medium
A14: F-13 | B14: Partially resolved | C14: Mild wheeze is marked 'superseded' in airway and collapse | D14: Grade 3 'mild bronchospasm, responds to treatment' and grade 4 'severe bronchospasm, not responding' describe the same organ at different severity, so the mild wording would contradict the state. The WAO inclusion rule ('any symptom from grades 1 or 3 is included') is kept for every other symptom. UPDATE (24 Sep 2026, RCUK 2021 and EAACI 2021 read): No guideline states that mild wheeze must stop being mentioned once the state worsens. RCUK p.21 says breathing problems 'can vary from mild bronchospasm to life-threatening asthma', which supports treating them as one severity continuum. | E14: Keep the 'superseded' rule as a documented consistency decision. Optionally merge mild and severe wheeze into one symptom_id with severity levels. Expert to confirm. | F14: Medium
A15: F-14 | B15: Resolved | C15: Forbidden lists are now generated, uterine cramps added | D15: Forbidden = every symptom whose first_state is later than the current state, matched by symptom_id (fixes 9 missing entries in early_reaction, 4 in airway_compromise and the name mismatches such as 'voice change' vs 'hoarse/changed voice'). Uterine cramps (grade 3, WAO_Grade_Map) was missing from State_Symptoms and is added as female-only. | E15: Do not edit forbidden rows by hand. Change first_state in Symptom_Master and regenerate. | F15: Low
A16: F-15 | B16: Resolved | C16: Completed State_Actions tiers are read from WAO's indication wording | D16: Every state x action pair is now explicit (16 actions x 3 states). 'conditional' = only under a condition the PDF states; 'neutral' = the PDF gives no indication in that state, which is not proof that the action is harmless. CPR (ANA-013) in early and airway state is neutral because the PDF only says 'where indicated'. UPDATE (24 Sep 2026, RCUK 2021 and EAACI 2021 read): RCUK Fig. 6 p.25, Fig. 7 p.36 and pp.26, 31, 34, 37, 39: CPR only in cardiac arrest (pp.26, 39), so 'neutral' in early/airway is source-consistent; after arrest IM adrenaline is unreliable and IV/IO adrenaline is used (p.26). IV fluid bolus is for hypotension/shock or poor response to the first dose (p.31), so 'conditional' rather than 'neutral' in early/airway. Adrenaline infusion is for refractory anaphylaxis after two IM doses (pp.34, 37). Glucagon is for patients on beta-blockers who remain refractory to infusion and fluids (p.39). Antihistamines are third-line and steroids are not routine (pp.9, 32-33). Oxygen is recommended for all patients (RCUK p.31, EAACI p.365) but is supportive, not the required action. Some current State_Actions and Transitions entries differ from this (see F-26). UPDATE (24 Sep 2026): Tiers realigned with Bundle_Sequence; see F-26 for the exact changes applied to State_Actions and Transitions. Expert to confirm CPR and infusion tiers at final validation. | E16: Align State_Actions and Transitions with Bundle_Sequence (F-26) before final validation. Expert to confirm CPR and infusion tiers. | F16: Partially resolved
A17: F-16 | B17: Medium | C17: Wording in Hints, Observable_Signs and Action_Aliases is derived | D17: Content follows PDF terms (see the source columns) but the phrasing is ours, not WAO text. Brand names such as EpiPen or Auvi-Q appear in the PDF only in reference titles, so they are not in Action_Aliases. Hint timing and visibility are Brain 1's job. | E17: Do not quote hint or cue wording as WAO text. Add trainee phrase variants (how people actually say it) as an NLP task.
A18: F-17 | B18: Open — FSM designer scope | C18: Time values in State_Variables and Hints are real clinical minutes | D18: The 5-15 min repeat interval and similar values are real time. The PDF gives no penalty for repeating epinephrine too early or too late. UPDATE (24 Sep 2026): Confirmed as a design decision, not a sourcing gap: no guideline gives a penalty for early/late repeat dosing. Time-compression factor and any repeat-timing scoring are the FSM designer's decision (same scope as F-24/F-25). | E18: Convert with the time-compression factor before use. Decide any repeat-timing scoring with the expert. | F18: Medium
A19: F-18 | B19: Resolved | C19: Observable_Signs holds only signs the PDF names | D19: Cyanosis, pallor, sweating, use of accessory muscles and tachycardia are NOT in the PDF, so they were not added. WAO also gives no SpO2 cut-off for hypoxemia. UPDATE (24 Sep 2026, RCUK 2021 and EAACI 2021 read): Second sources found. RCUK p.21 and Fig. 6 p.25: increased work of breathing, fatigue, hypoxaemia (SpO2 <94%), central cyanosis, pale and clammy skin, significant tachycardia, hypotension. EAACI Fig. 1 p.364: dyspnoea, tachypnoea, cyanosis, tachycardia, dizziness, fainting, confusion. Sweating and accessory-muscle use are not named as such in either guideline. UPDATE (25 Sep 2026): Added SYM-031 (cyanosis), SYM-032 (increased work of breathing), SYM-033 (pale, clammy skin) and SYM-034 (tachycardia) to Symptom_Master, and SIGN-023 to SIGN-026 to Observable_Signs, all evidence_level 'Derived', citing RCUK p.21/Fig.6 p.25 and EAACI Fig.1 p.364. Sweating and accessory-muscle use intentionally NOT added (not named in either guideline). SpO2 <94% kept as reference threshold only (already noted against SIGN-021 hypoxemia). | E19: Done — 4 new symptoms + 4 new observable signs added; see Symptom_Master and Observable_Signs. | F19: Low
A20: F-19 | B20: Resolved | C20: Post-recovery actions use PS-xx IDs and are neutral before the Stable state | D20: PS-01 to PS-15 (Post_Stable_Brain3) are scored by Brain 3 after recovery. 'Neutral before stable' is a design choice: the PDF says anaphylaxis needs immediate management (p.14) but does not tier discharge actions by state. UPDATE (24 Sep 2026, RCUK 2021 and EAACI 2021 read): RCUK pp.7, 42-45 and EAACI p.366 (Box 4) place observation, auto-injector prescription with training, written action plan, allergy referral and record keeping after treatment and stabilisation. Neither guideline tiers them by FSM state, so 'neutral before stable' is consistent with the sources. Two corrections: (1) RCUK pp.7, 45 recommend an auto-injector for all patients except those with a drug-induced reaction (unless future exposure is hard to avoid), so PS-02 needs this condition. (2) The acute tryptase sample is taken during the reaction (see F-31). | E20: Add the drug-induced exception to PS-02. Handle the acute tryptase sample under F-31. No other change. | F20: Low
A21: F-20 | B21: Resolved (see F-26) | C21: Bundle rule for FSM state transitions (was undecided) | D21: RCUK 2021's own algorithm (Fig. 6/7) makes IM adrenaline the single required action for transitioning early_reaction and airway_compromise to stable; all other actions (remove trigger, call for help, position, O2, monitor, fluids) are supportive/conditional, not required for the transition. This matches the design already used in Transitions/State_Actions. | E21: Source confirms the bundle rule for early_reaction. However, State_Actions and Transitions still list oxygen (and, in collapse, IV access and fluids) as transition triggers, which differs from Bundle_Sequence. See F-26.
A22: F-21 | B22: Resolved | C22: Repeat-dose interval conflict (WAO 5-15 min vs a single number) | D22: RCUK 2021 (most recent, GRADE-based) specifies a fixed 5-minute repeat interval, not a 5-15 min range. WAO's wider range and EAACI's '5-10 min' checklist are kept as alternatives. | E22: RCUK's 5 min is used as the default in Bundle_Sequence and Repeat_Interval_Comparison. Confirm with expert before hard-coding into Brain 1 timers.
A23: F-22 | B23: Resolved | C23: Fluid bolus conflict (WAO's two internally-conflicting figures, F-03) | D23: A third, more recent and internally-consistent guideline (RCUK 2021) is now the default: child 10 mL/kg, adult 500-1000 mL rapid bolus, non-glucose crystalloid, up to 3-5 L in adults for severe shock. WAO's two figures and EAACI's figures are kept for comparison. | E23: See Fluid_Bolus_Comparison. RCUK figure used as the workbook default; expert to confirm at final validation.
A24: F-23 | B24: Partially resolved | C24: Timers (item 3): exact anchor times | D24: RCUK 2021's own Figure 4 (p.17) independently reports the same anchor times as Pumphrey 2000 (food ~30 min, venom 10-15 min, IV medication ~5 min to arrest), which strengthens confidence in these numbers as a second, current, national-guideline source. | E24: The split of a disease's total time across the 3 FSM states, and the sim-time compression factor, are still design decisions — not resolved by any guideline.
A25: F-24 | B25: Still open | C25: Time penalty (item 2): no numeric value in any guideline | D25: RCUK 2021 adds further real-world evidence that IV bolus adrenaline and sudden posture change are dangerous (RCUK p.30: fatalities have occurred in the UK from inappropriate IV adrenaline given for non-anaphylaxis allergic reactions; RCUK pp.19, 26: sudden posture change is associated with collapse and death), but gives no numeric penalty for the FSM's timer. UPDATE (24 Sep 2026, RCUK 2021 and EAACI 2021 read): The figure 'three UK deaths' that appeared in the earlier wording is not stated in the RCUK PDF text and was removed. | E25: Still requires a numeric decision by the FSM designer and pilot testing. Guidelines give direction only: C-01 and C-04 carry documented deaths, C-02 causes hypotension, C-03 delays adrenaline.
A26: F-25 | B26: Resolved (numeric modifiers); escalation lines still open | C26: Escalation lines (item 6) and Worm 2018 numeric modifiers (item 4) | D26: Neither RCUK 2021 nor EAACI 2021 supplies dialogue text for gradual symptom escalation, or numeric odds ratios for cofactors/comorbidities. UPDATE (24 Sep 2026, RCUK 2021 and EAACI 2021 read): Patient-language cues can be taken from EAACI Boxes 6-7 pp.369-370 (persistent cough, hoarse voice, difficulty swallowing, swollen tongue, difficult or noisy breathing, wheeze, persistent dizziness, pale or floppy, suddenly sleepy, collapse) and RCUK pp.21-22 (throat feels as if it is closing, anxiety, 'sense of impending doom', confusion, agitation). The Worm 2018 odds ratios are in neither PDF. UPDATE (25 Sep 2026, Worm et al. 2018, Allergy 73(6):1322-1330, doi:10.1111/all.13380, read): Numeric odds ratios for cofactors/comorbidities now sourced from Table 1 of this paper (European Anaphylaxis Registry, n=7316). See new 'Worm2018_Modifiers' sheet for the full OR/CI table (NIAID/FAAN and Ring & Messmer models). Escalation dialogue lines (item 6) remain team-written, per original recommended_action. | E26: Numeric modifiers: DONE — use Worm2018_Modifiers sheet values, tagged evidence_level 'Empirical (Worm 2018)'. Escalation lines: team still writes the dialogue, maps each line to a symptom_id, tags evidence_level 'Derived (team-written)'. | F26: Still open
A27: F-26 | B27: Resolved | C27: State_Actions and Transitions differ from Bundle_Sequence | D27: Transitions requires ANA-004 and ANA-007 for airway_compromise -> stable, and ANA-004, ANA-008, ANA-009 and ANA-007 for cardiovascular_collapse -> stable. State_Actions marks ANA-007 (airway) and ANA-007/008/009 (collapse) as 'correct' with triggers_transition = Yes. Bundle_Sequence (RCUK Fig. 6/7, pp.25, 31, 34-37) makes IM adrenaline the only required action in early_reaction and airway_compromise (oxygen = No), and in collapse requires IM doses until two have been given, then an adrenaline infusion; fluids are conditional; CPR if arrested. State_Actions collapse and airway notes also say 'every 5-15 min' (WAO) while Bundle_Sequence uses 5 min (F-21), and Actions/Calculators still use 0.01 mg/kg with a 0.3 mg child cap (WAO, F-05) while Epinephrine_Doses uses RCUK as default. F-20 says no change is needed; that is not correct for the current sheets. UPDATE (24 Sep 2026): Applied: oxygen (ANA-007) is now supportive, not a transition trigger, in every state. IV fluids (ANA-009) are conditional (not neutral) in early_reaction and airway_compromise. Adrenaline infusion (ANA-014) and glucagon (ANA-015) are neutral in airway_compromise (both require the refractory/cardiovascular_collapse state per RCUK p.34, p.37, p.39) and conditional/correct in cardiovascular_collapse. In cardiovascular_collapse, the required transition action is now two IM adrenaline doses (ANA-004) followed by the adrenaline infusion (ANA-014); oxygen and IV access are supportive, IV fluids are conditional, and CPR (ANA-013) triggers transition only if the patient has arrested. Transitions rows for airway_compromise and cardiovascular_collapse updated to match. F-20's 'no change needed' wording is now correct. | E27: FSM team to choose: keep the current bundle as a design choice and reword F-20, or align State_Actions and Transitions with Bundle_Sequence. RCUK-aligned suggestion: oxygen supportive (not a trigger) in all states; IV access/fluids conditional in early/airway; collapse triggered by IM doses (until two), infusion (ANA-014) and CPR if arrested; glucagon conditional in collapse only. Not applied automatically because it changes FSM logic. | F27: High
A28: F-27 | B28: Resolved | C28: Missing and conflicting doses in Action_Aliases | D28: Action_Aliases showed 'No dose in PDF' for ANA-011, 012, 014, 015, 016 and 017 (WAO gives none). RCUK 2021 gives them (Appendix 3 p.57; p.30; Table 4 p.32) and they are now entered in Action_Aliases. Conflict: nebulised adrenaline is 5 mL of 1 mg/mL, i.e. 5 mg (RCUK p.30), but 1 mg in 4 mL 0.9% NaCl (EAACI Fig. 1 p.364). Neither guideline gives a chlorphenamine dose; RCUK recommends an oral non-sedating antihistamine such as cetirizine after stabilisation (Table 4 p.32). UPDATE (24 Sep 2026): Doses added to Action_Aliases for ANA-011, 012, 014, 015, 016 and 017 from RCUK Appendix 3 p.57, p.30 and Table 4 p.32. | E28: Use RCUK as the default and keep the EAACI value as a comparison. Confirm the nebulised dose with the expert. | F28: Medium
A29: F-28 | B29: Resolved | C29: Oxygen flow rate differs between guidelines | D29: WAO Fig. 4: 6-8 L/min by face mask. EAACI Fig. 1 p.364: 10 L/min with a reservoir bag. RCUK p.31: highest concentration possible with a reservoir mask, then titrate to SpO2 94-98% (88-92% if at risk of hypercapnic respiratory failure). Global_Rules D16, Actions D7 and Action_Aliases G7 use the WAO figure. UPDATE (24 Sep 2026): Global_Rules D16/E16, Actions D7/E7 and Action_Aliases (ANA-007) updated to RCUK as the default oxygen instruction, with WAO and EAACI flow rates kept as comparison text. SpO2 titration needs the SpO2 value from the vitals data (still blank per F-02, designer/other-dataset scope). | E29: Default to RCUK and keep WAO and EAACI as comparison. Titration to SpO2 needs the SpO2 value from the vitals data. | F29: Medium
A30: F-29 | B30: Resolved | C30: EAACI dose bands are also treatment doses | D30: Epinephrine_Doses labels the EAACI rows as auto-injector prescribing only. EAACI Fig. 1 p.364 also gives treatment doses (0.15 mg for <25-30 kg, 0.3 mg for >=25-30 kg, 0.5 mg may be considered for adolescents and adults), and p.365 states the healthcare-setting IM dose is 0.01 mg/kg, with 0.5 mg or a repeated 0.3 mg considered in severe reactions. UPDATE (24 Sep 2026): Epinephrine_Doses EAACI rows corrected: they are also healthcare-provider treatment doses (EAACI Fig. 1 p.364), not only auto-injector prescribing bands. Added the EAACI 0.01 mg/kg healthcare-setting rule (p.365) as a new row. | E30: Update the EAACI note in Epinephrine_Doses. RCUK remains the default. | F30: Low
A31: F-30 | B31: Resolved | C31: Observation duration differs between guidelines | D31: RCUK pp.42-43: fast-track 2 h, minimum 6 h, at least 12 h depending on risk. EAACI p.366: monitor 6-8 h with respiratory compromise and at least 12-24 h with hypotension. Discharge_Observation contains RCUK only. UPDATE (24 Sep 2026): Added an EAACI 2021 comparison row to Discharge_Observation (p.366: 6-8 h respiratory compromise, 12-24 h hypotension). RCUK remains the default. | E31: Keep RCUK as the default and add an EAACI comparison row. | F31: Low
A32: F-31 | B32: Resolved | C32: Acute tryptase sample is not modelled | D32: RCUK p.41 and EAACI p.361 recommend a tryptase sample as soon as feasible without delaying treatment, a second sample 1-2 h (no later than 4 h) after onset, and a baseline at least 24 h after resolution. RCUK Fig. 7 p.36 includes 'take blood sample for mast cell tryptase'. Post_Stable_Brain3 contains only the baseline (PS-07) and Actions has no action for the acute sample. UPDATE (24 Sep 2026): Added action ANA-018 'take blood sample for mast cell tryptase' (Actions, Action_Aliases, State_Actions in all 3 states, tier supportive, must not delay adrenaline). PS-07 keeps the baseline (>=24 h) sample; ANA-018 covers the acute/2-hour sample. | E32: Team decision: add an action (for example ANA-018 'take tryptase sample') as supportive in all states that must not delay adrenaline, and keep PS-07 for the baseline. | F32: Medium

Sheet WAO_Grade_Map
A1: table7_grade | B1: organ_systems_and_symptoms | C1: anaphylaxis_per_paper | D1: fsm_state_v2 | E1: confidence | F1: source
A2: 1 | B2: One organ system present. Cutaneous: urticaria and/or erythema-warmth and/or pruritus (other than at an injection site); tingling or itching of the lips, or angioedema (not laryngeal). Upper respiratory: nasal symptoms (sneezing, rhinorrhea, pruritus, congestion); throat-clearing (itchy throat); cough not related to bronchospasm. Conjunctival: erythema, pruritus, tearing. Other: nausea, metallic taste. | C2: No (header 'Not anaphylaxis') | D2: Not a state (pre-anaphylaxis) | E2: Verified on rendered PDF pp.13-14 | F2: Table 7 pp.13-14
A3: 2 | B3: Symptoms/signs from 2 or more organ systems (the cell text is cut off in the PDF at '>=2 organ'). | C3: No (header 'Not anaphylaxis') | D3: Not a state (pre-anaphylaxis) | E3: Verified on rendered PDF p.13 | F3: Table 7 p.13
A4: 3 | B4: Lower airway: mild bronchospasm (cough, wheezing, shortness of breath) which responds to treatment. And/or gastrointestinal: abdominal cramps and/or vomiting/diarrhea. Other: uterine cramps. Any grade 1 symptom is included. | C4: Header says ANAPHYLAXIS; p.17 text adds that only some grade 3 reactions fit the definition | D4: early_reaction | E4: Verified on rendered PDF p.13 | F4: Table 7 p.13; p.17
A5: 4 | B5: Lower airway: severe bronchospasm not responding or worsening in spite of treatment. And/or upper airway: laryngeal edema with stridor. Any symptom from grades 1 or 3 is included. | C5: Yes (header ANAPHYLAXIS) | D5: airway_compromise | E5: Verified on rendered PDF p.13 | F5: Table 7 p.13
A6: 5 | B6: Lower or upper airway: respiratory failure. And/or cardiovascular: collapse/hypotension. And/or loss of consciousness (vasovagal excluded). Any symptom from grades 1, 3 or 4 is included. | C6: Yes (header ANAPHYLAXIS) | D6: cardiovascular_collapse | E6: Verified on rendered PDF p.13 | F6: Table 7 p.13

Sheet Global_Rules
A1: rule_id | B1: category | C1: parameter | D1: value | E1: source
A2: G-01 | B2: Diagnosis | C2: Criterion 1 | D2: Acute onset (minutes to several hours) of skin and/or mucosal involvement (generalized hives, pruritus/flushing, swollen lips-tongue-uvula) AND at least one of: (a) respiratory compromise (dyspnea, wheeze-bronchospasm, stridor, reduced PEF, hypoxemia); (b) reduced BP or end-organ dysfunction (hypotonia/collapse, syncope, incontinence); (c) severe GI symptoms (severe crampy abdominal pain, repetitive vomiting), especially after non-food allergens. Symptoms appear more or less simultaneously. | E2: Table 2 p.5; Fig. 1 p.6; p.9
A3: G-02 | B3: Diagnosis | C3: Criterion 2 | D3: Acute onset of hypotension OR bronchospasm OR laryngeal involvement (stridor, vocal changes, odynophagia) after exposure to a known or highly probable allergen for that patient, even without typical skin involvement. | E3: Table 2 p.5; Fig. 1 p.6
A4: G-03 | B4: Diagnosis | C4: Skin signs absent | D4: Skin signs are absent in 10-20% of anaphylaxis reactions (supports a no-skin scenario variant). | E4: p.7
A5: G-04 | B5: Hypotension | C5: All ages | D5: Decrease in systolic BP greater than 30% from the person's baseline. | E5: Table 2 footnote a
A6: G-05 | B6: Hypotension | C6: Adults and children over 10 y | D6: Systolic BP < 90 mmHg. | E6: Table 2 footnote a
A7: G-06 | B7: Hypotension | C7: Infants and children under 10 y | D7: Systolic BP < 70 mmHg + (2 x age in years). | E7: Table 2 footnote a
A8: G-07 | B8: Epinephrine | C8: Route and site | D8: Intramuscular, mid-anterolateral thigh (vastus lateralis). | E8: Fig. 4 p.11; p.15
A9: G-08 | B9: Epinephrine | C9: Concentration | D9: 1 mg/mL (1:1000) recommended for IM injection (allows an appropriate volume). | E9: Table 6 footnote a, p.12
A10: G-09 | B10: Epinephrine | C10: Dose (healthcare professional) | D10: 0.01 mg/kg body weight, maximum total 0.5 mg IM. Fig. 4: maximum 0.5 mg adult or 0.3 mg child. See Epinephrine_Doses. | E10: p.15; Table 6 p.12; Fig. 4
A11: G-10 | B11: Epinephrine | C11: Repeat dosing | D11: Repeat every 5-15 min if symptoms are refractory. Most patients respond to 1 or 2 doses. | E11: p.15; Fig. 4
A12: G-11 | B12: Epinephrine | C12: Auto-injector technique | D12: Inject into mid-anterolateral thigh, hold in place about 3-10 s, then call for medical assistance. | E12: p.16
... A23: G-22 | B23: Diagnostics | C23: Serum tryptase | D23: Rises from 15 min to 3 h after onset, peaking at 1-2 h. Normal level does not exclude anaphylaxis. Measure baseline at least 24 h after symptoms resolve. | E23: p.17

Sheet Epinephrine_Doses
A1: guideline | B1: recommended_default | C1: patient_group | D1: dose | E1: concentration | F1: route_and_prep | G1: repeat_interval | H1: source | I1: note
A2: RCUK 2021 | B2: Yes | C2: Adult and child > 12 years | D2: 500 micrograms IM (0.5 mL) | E2: 1 mg/mL (1:1000) | F2: IM, ampoule + syringe (preferred in healthcare settings over auto-injector) | G2: Repeat after 5 min if no improvement | H2: RCUK 2021 p.29 | I2: Give 300 micrograms (0.3 mL) if the child is small or prepubertal
A3: RCUK 2021 | B3: Yes | C3: 6-12 years | D3: 300 micrograms IM (0.3 mL) | E3: 1 mg/mL (1:1000) | F3: IM, ampoule + syringe | G3: Repeat after 5 min if no improvement | H3: RCUK 2021 p.29
A4: RCUK 2021 | B4: Yes | C4: 6 months - 6 years | D4: 150 micrograms IM (0.15 mL) | E4: 1 mg/mL (1:1000) | F4: IM, ampoule + syringe | G4: Repeat after 5 min if no improvement | H4: RCUK 2021 p.29
A5: RCUK 2021 | B5: Yes | C5: Under 6 months | D5: 100-150 micrograms IM (0.1-0.15 mL) | E5: 1 mg/mL (1:1000) | F5: IM, ampoule + syringe | G5: Repeat after 5 min if no improvement | H5: RCUK 2021 p.29 | I5: First guideline to give a specific dose for this age band
A6: WAO 2020 | B6: No (superseded by RCUK default above) | C6: General rule (weight-based) | D6: 0.01 mg/kg, max 0.5 mg | E6: 1 mg/mL (1:1000) | F6: IM, mid-anterolateral thigh | G6: Repeat every 5-15 min if refractory | H6: WAO p.15; Table 6 p.12 | I6: Wider repeat window (5-15 min) than RCUK's fixed 5 min; see Repeat_Interval_Comparison
A7: WAO 2020 | B7: No | C7: Infant under 10 kg | D7: 0.01 mg/kg | E7: 1 mg/mL (1:1000) | F7: IM, mid-anterolateral thigh | G7: Repeat every 5-15 min if refractory | H7: WAO Table 6 p.12
A8: WAO 2020 | B8: No | C8: Child 1-5 years | D8: 0.15 mg (0.15 mL) | E8: 1 mg/mL (1:1000) | F8: IM, mid-anterolateral thigh | G8: Repeat every 5-15 min if refractory | H8: WAO Table 6 p.12 | I8: Same fixed dose as RCUK's 6mo-6y band
A9: WAO 2020 | B9: No | C9: Child 6-12 years | D9: 0.3 mg (0.3 mL) | E9: 1 mg/mL (1:1000) | F9: IM, mid-anterolateral thigh | G9: Repeat every 5-15 min if refractory | H9: WAO Table 6 p.12 | I9: Matches RCUK's 6-12y dose
A10: WAO 2020 | B10: No | C10: Teenager / adult | D10: 0.5 mg (0.5 mL) | E10: 1 mg/mL (1:1000) | F10: IM, mid-anterolateral thigh | G10: Repeat every 5-15 min if refractory | H10: WAO Table 6 p.12 | I10: Matches RCUK's adult/>12y dose
A11: EAACI 2021 | B11: No (RCUK remains the workbook default) | C11: Children 7.5-25/30 kg (auto-injector) | D11: 0.15 mg auto-injector | E11: N/A (fixed-dose device) | F11: IM, auto-injector or ampoule + syringe (EAACI Fig. 1 treatment algorithm, p.364, uses the same doses for healthcare treatment) | G11: Repeat per device label | H11: EAACI p.364-365 | I11: This dose is also used for healthcare-provider treatment, not only for auto-injector prescribing (EAACI Fig. 1 p.364); matches the RCUK 6mo-6y/6-12y bands.
A12: EAACI 2021 | B12: No (RCUK remains the workbook default) | C12: Children over 25-30 kg (auto-injector) | D12: 0.3 mg auto-injector | E12: N/A (fixed-dose device) | F12: IM, auto-injector or ampoule + syringe (EAACI Fig. 1 treatment algorithm, p.364) | G12: Repeat per device label | H12: EAACI p.364-365 | I12: Also an EAACI healthcare-provider treatment dose (Fig. 1 p.364), not only an auto-injector band; matches the RCUK adult/>12y and 6-12y bands.
A13: EAACI 2021 | B13: No (RCUK remains the workbook default) | C13: Adolescents and adults at risk (auto-injector) | D13: At least 0.3 mg auto-injector | E13: N/A (fixed-dose device) | F13: IM, auto-injector or ampoule + syringe (EAACI Fig. 1 treatment algorithm, p.364) | G13: Repeat per device label | H13: EAACI p.364-365 | I13: EAACI Fig. 1 p.364 also allows this as a treatment dose, and p.365 states the general healthcare-setting IM dose is 0.01 mg/kg, with 0.5 mg or a repeated 0.3 mg considered in severe reactions (0.5 mg device considered if overweight or previous life-threatening reaction, EAACI p.365).
A14: EAACI 2021 | B14: No (RCUK remains the workbook default) | C14: General rule (weight-based), healthcare setting | D14: 0.01 mg/kg IM; 0.5 mg or a repeated 0.3 mg may be considered in severe reactions | E14: 1 mg/mL (1:1000) | F14: IM, ampoule + syringe | G14: Not specified for the ampoule route in EAACI | H14: EAACI 2021 p.365 | I14: Confirms EAACI treatment dosing is not limited to auto-injector prescribing.

Sheet States
A1: state_id | B1: state_name | C1: wao_table7_grade | D1: wao_basis | E1: entry_requirement | F1: vitals_from_WAO | G1: vitals_other | H1: on_correct | I1: on_timer_expiry_or_no_action | J1: source_note
A2: early_reaction | B2: Early Reaction | C2: 3 | D2: Table 7 grade 3 (mild bronchospasm and/or GI) AND Table 2 criterion 1 met. Table 7 lists grade 3 under ANAPHYLAXIS, but the p.17 text says only some grade 3 reactions fit the definition, so this state is the subset meeting criterion 1. | E2: Skin/mucosal component AND at least one qualifier (mild wheeze/shortness of breath, or severe/repetitive GI). See State_Symptoms criterion1_role. No-skin variant: Table 2 criterion 2 (skin signs absent in 10-20%, G-03). | F2: SBP stays above the hypotension threshold (G-04 to G-06) | G2: HR/RR/SpO2 not given by WAO; use MIMIC-IV-ED | H2: stable | I2: airway_compromise | J2: Table 2 p.5; Table 7 pp.13-14; Fig. 4
A3: airway_compromise | B3: Airway Compromise | C3: 4 | D3: Table 7 grade 4: severe bronchospasm not responding or worsening despite treatment, and/or laryngeal edema with stridor. | E3: Stridor, voice change or painful swallowing, or severe bronchospasm. May also carry all early_reaction symptoms. | F3: Hypoxemia is a criterion but no SpO2 cut-off is given; SBP stays above hypotension threshold | G3: Use MIMIC-IV-ED for HR/RR/SpO2 | H3: stable | I3: cardiovascular_collapse | J3: Table 7 pp.13-14
A4: cardiovascular_collapse | B4: Cardiovascular Collapse | C4: 5 | D4: Table 7 grade 5: respiratory failure and/or cardiovascular collapse/hypotension and/or loss of consciousness (vasovagal excluded). | E4: Hypotension per G-04 to G-06, or collapse/loss of consciousness, or respiratory failure. | F4: Hypotension per G-04 to G-06 (adult SBP < 90 or >30% fall from baseline) | G4: Use MIMIC-IV-ED. PEA/arrest rhythm is your design choice; WAO only says CPR with continuous compressions 'where indicated' | H4: stable | I4: scenario_end (design choice, see F-02) | J4: Table 7 pp.13-14; p.15
A5: stable | B5: Stable | C5: not defined by WAO | D5: Response to epinephrine (most respond to 1-2 doses). WAO does not define a 'stable' state. | E5: Symptoms resolving after treatment | F5: None defined | G5: Vitals trend back gradually; not instantaneous | H5: (terminal) | I5: (terminal) | J5: Fig. 4; Post_Stable_Brain3 sheet

Sheet State_Symptoms
A1: state_id | B1: symptom_id | C1: symptom | D1: status | E1: modality | F1: patient_can_report | G1: trainee_can_observe | H1: applies_to | I1: organ_system | J1: wao_table7_grade | K1: criterion1_role | L1: inherited_from_earlier_state | M1: evidence_level | N1: source | O1: note
A2: early_reaction | B2: SYM-001 | C2: itchy skin | D2: allowed | E2: subjective | F2: Yes (full sentences) | G2: No (only if patient reports it) | H2: all | I2: Cutaneous | J2: 1 | K2: skin/mucosal component | L2: No | M2: Direct | N2: Table 2 (pruritus); Table 7 grade 1
A3: early_reaction | B3: SYM-002 | C3: hives | D3: allowed | E3: observed | F3: not needed (observed) | G3: Yes | H3: all | I3: Cutaneous | J3: 1 | K3: skin/mucosal component | L3: No | M3: Direct | N3: Table 2; Table 7 grade 1 (urticaria)
A4: early_reaction | B4: SYM-003 | C4: flushing | D4: allowed | E4: observed | F4: not needed (observed) | G4: Yes | H4: all | I4: Cutaneous | J4: 1 | K4: skin/mucosal component | L4: No | M4: Direct | N4: Table 2; Table 7 grade 1 (erythema-warmth)
A5: early_reaction | B5: SYM-004 | C5: sense of heat | D5: allowed | E5: subjective | F5: Yes (full sentences) | G5: No (only if patient reports it) | H5: all | I5: Cutaneous | J5: not graded | K5: supporting | L5: No | M5: Direct | N5: p.16 recognition symptoms
A6: early_reaction | B6: SYM-005 | C6: tingling/itching of lips or extremities | D6: allowed | E6: subjective | F6: Yes (full sentences) | G6: No (only if patient reports it) | H6: all | I6: Cutaneous | J6: 1 | K6: supporting | L6: No | M6: Direct | N6: Table 7 grade 1 (lips); p.16 (extremities)
A7: early_reaction | B7: SYM-006 | C7: swollen lips/tongue (non-laryngeal) | D7: allowed | E7: observed | F7: not needed (observed) | G7: Yes | H7: all | I7: Cutaneous | J7: 1 | K7: skin/mucosal component | L7: No | M7: Direct | N7: Table 2; Table 7 grade 1 (angioedema, not laryngeal)
A8: early_reaction | B8: SYM-007 | C8: sneezing, runny or blocked nose | D8: allowed | E8: both | F8: Yes (full sentences) | G8: Yes | H8: all | I8: Upper respiratory | J8: 1 | K8: supporting | L8: No | M8: Direct | N8: Table 7 grade 1 (nasal symptoms)
A9: early_reaction | B9: SYM-008 | C9: itchy watery eyes | D9: allowed | E9: both | F9: Yes (full sentences) | G9: Yes | H9: all | I9: Conjunctival | J9: 1 | K9: supporting | L9: No | M9: Direct | N9: Table 7 grade 1
A10: early_reaction | B10: SYM-009 | C10: throat clearing | D10: allowed | E10: both | F10: Yes (full sentences) | G10: Yes | H10: all | I10: Upper respiratory | J10: 1 | K10: supporting | L10: No | M10: Direct | N10: Table 7 grade 1 (itchy throat)
A11: early_reaction | B11: SYM-010 | C11: cough | D11: allowed | E11: both | F11: Yes (full sentences) | G11: Yes | H11: all | I11: Upper respiratory | J11: 1 | K11: supporting | L11: No | M11: Direct | N11: Table 7 grade 1 (cough not related to bronchospasm)
A12: early_reaction | B12: SYM-011 | C12: mild wheeze or shortness of breath | D12: allowed | E12: both | F12: Yes (full sentences) | G12: Yes | H12: all | I12: Lower respiratory | J12: 3 | K12: qualifier: respiratory compromise | L12: No | M12: Direct | N12: Table 2 (a); Table 7 grade 3 (mild bronchospasm, responds to treatment)
A13: early_reaction | B13: SYM-012 | C13: nausea | D13: allowed | E13: subjective | F13: Yes (full sentences) | G13: No (only if patient reports it) | H13: all | I13: Gastrointestinal | J13: 1 | K13: supporting | L13: No | M13: Direct | N13: Table 7 grade 1 (other)
... A16: early_reaction | B16: SYM-015 | C16: vomiting or diarrhea | D16: allowed | E16: both | F16: Yes (full sentences) | G16: Yes | H16: all | I16: Gastrointestinal | J16: 3 | K16: qualifier: severe GI (only if repetitive) | L16: No | M16: Direct | N16: Table 2 (c); Table 7 grade 3
A17: early_reaction | B17: SYM-016 | C17: uterine cramps (female patients) | D17: allowed | E17: subjective | F17: Yes (full sentences) | G17: No (only if patient reports it) | H17: female patients only | I17: Other | J17: 3 | K17: supporting | L17: No | M17: Direct | N17: Table 7 p.13 (grade 3, 'Other') | O17: Use only for female patients.
A18: early_reaction | B18: SYM-017 | C18: dizziness | D18: allowed | E18: subjective | F18: Yes (full sentences) | G18: No (only if patient reports it) | H18: all | I18: Neurological/CV | J18: not graded | K18: supporting | L18: No | M18: Direct | N18: p.16 recognition symptoms
A19: early_reaction | B19: SYM-018 | C19: stridor | D19: forbidden | E19: observed | H19: all | I19: Upper airway | J19: 4 | M19: Direct | N19: Table 2; Table 7 grade 4 (laryngeal edema with stridor)
A20: early_reaction | B20: SYM-019 | C20: hoarse/changed voice | D20: forbidden | E20: both | H20: all | I20: Upper airway | J20: not graded | M20: Direct | N20: Table 2 footnote c (vocal changes)
A21: early_reaction | B21: SYM-020 | C21: painful swallowing | D21: forbidden | E21: subjective | H21: all | I21: Upper airway | J21: not graded | M21: Direct | N21: Table 2 footnote c (odynophagia)
A22: early_reaction | B22: SYM-021 | C22: throat or tongue tightness | D22: forbidden | E22: subjective | H22: all | I22: Upper airway | J22: not graded | M22: Derived | N22: Patient-language rendering of laryngeal involvement (F-08)
A23: early_reaction | B23: SYM-022 | C23: marked shortness of breath | D23: forbidden | E23: both | H23: all | I23: Lower respiratory | J23: 4 | M23: Derived | N23: Patient-language rendering of severe bronchospasm, Table 7 grade 4 (F-08)
A24: early_reaction | B24: SYM-023 | C24: wheeze not improving with treatment | D24: forbidden | E24: observed | H24: all | I24: Lower respiratory | J24: 4 | M24: Direct | N24: Table 7 grade 4 (not responding or worsening)
A25: early_reaction | B25: SYM-024 | C25: drooling (paediatric variant) | D25: forbidden | E25: observed | H25: paediatric variant only | I25: Upper airway | J25: not graded | M25: Direct | N25: p.17: drooling may apply in paediatric setting
A26: early_reaction | B26: SYM-025 | C26: collapse/limpness (hypotonia) | D26: forbidden | E26: observed | H26: all | I26: Cardiovascular | J26: 5 | M26: Direct | N26: Table 2 (b); Table 7 grade 5
A27: early_reaction | B27: SYM-026 | C27: fainting (syncope) | D27: forbidden | E27: observed | H27: all | I27: Cardiovascular | J27: not graded | M27: Direct | N27: Table 2 (b)
A28: early_reaction | B28: SYM-027 | C28: loss of consciousness | D28: forbidden | E28: observed | H28: all | I28: Neurological | J28: 5 | M28: Direct | N28: Table 7 grade 5 (vasovagal excluded)
A29: early_reaction | B29: SYM-028 | C29: incontinence | D29: forbidden | E29: observed | H29: all | I29: Other | J29: not graded | M29: Direct | N29: Table 2 (b)
A30: early_reaction | B30: SYM-029 | C30: respiratory failure | D30: forbidden | E30: observed | H30: all | I30: Lower respiratory | J30: 5 | M30: Direct | N30: Table 7 grade 5
A31: early_reaction | B31: SYM-030 | C31: hypotension (vital sign, not patient-spoken) | D31: forbidden | E31: measured | H31: all | I31: Cardiovascular | J31: 5 | M31: Direct | N31: Table 2 footnote a; Table 7 grade 5
A32: airway_compromise | B32: SYM-001 | C32: itchy skin | D32: allowed | E32: subjective | F32: Limited (short phrases) | G32: No (only if patient reports it) | H32: all | I32: Cutaneous | J32: 1 | K32: skin/mucosal component | L32: early_reaction | M32: Direct | N32: Table 2 (pruritus); Table 7 grade 1
A33: airway_compromise | B33: SYM-002 | C33: hives | D33: allowed | E33: observed | F33: not needed (observed) | G33: Yes | H33: all | I33: Cutaneous | J33: 1 | K33: skin/mucosal component | L33: early_reaction | M33: Direct | N33: Table 2; Table 7 grade 1 (urticaria)
A34: airway_compromise | B34: SYM-003 | C34: flushing | D34: allowed | E34: observed | F34: not needed (observed) | G34: Yes | H34: all | I34: Cutaneous | J34: 1 | K34: skin/mucosal component | L34: early_reaction | M34: Direct | N34: Table 2; Table 7 grade 1 (erythema-warmth)
A35: airway_compromise | B35: SYM-004 | C35: sense of heat | D35: allowed | E35: subjective | F35: Limited (short phrases) | G35: No (only if patient reports it) | H35: all | I35: Cutaneous | J35: not graded | K35: supporting | L35: early_reaction | M35: Direct | N35: p.16 recognition symptoms
A36: airway_compromise | B36: SYM-005 | C36: tingling/itching of lips or extremities | D36: allowed | E36: subjective | F36: Limited (short phrases) | G36: No (only if patient reports it) | H36: all | I36: Cutaneous | J36: 1 | K36: supporting | L36: early_reaction | M36: Direct | N36: Table 7 grade 1 (lips); p.16 (extremities)
A37: airway_compromise | B37: SYM-006 | C37: swollen lips/tongue (non-laryngeal) | D37: allowed | E37: observed | F37: not needed (observed) | G37: Yes | H37: all | I37: Cutaneous | J37: 1 | K37: skin/mucosal component | L37: early_reaction | M37: Direct | N37: Table 2; Table 7 grade 1 (angioedema, not laryngeal)
A38: airway_compromise | B38: SYM-007 | C38: sneezing, runny or blocked nose | D38: allowed | E38: both | F38: Limited (short phrases) | G38: Yes | H38: all | I38: Upper respiratory | J38: 1 | K38: supporting | L38: early_reaction | M38: Direct | N38: Table 7 grade 1 (nasal symptoms)
A39: airway_compromise | B39: SYM-008 | C39: itchy watery eyes | D39: allowed | E39: both | F39: Limited (short phrases) | G39: Yes | H39: all | I39: Conjunctival | J39: 1 | K39: supporting | L39: early_reaction | M39: Direct | N39: Table 7 grade 1
A40: airway_compromise | B40: SYM-009 | C40: throat clearing | D40: allowed | E40: both | F40: Limited (short phrases) | G40: Yes | H40: all | I40: Upper respiratory | J40: 1 | K40: supporting | L40: early_reaction | M40: Direct | N40: Table 7 grade 1 (itchy throat)
A41: airway_compromise | B41: SYM-010 | C41: cough | D41: allowed | E41: both | F41: Limited (short phrases) | G41: Yes | H41: all | I41: Upper respiratory | J41: 1 | K41: supporting | L41: early_reaction | M41: Direct | N41: Table 7 grade 1 (cough not related to bronchospasm)
A42: airway_compromise | B42: SYM-011 | C42: mild wheeze or shortness of breath | D42: superseded | E42: both | H42: all | I42: Lower respiratory | J42: 3 | M42: Direct | N42: Table 2 (a); Table 7 grade 3 (mild bronchospasm, responds to treatment) | O42: Same organ (lower airway) as SYM-022 / SYM-023: grade 3 'responds to treatment' is replaced by grade 4 'not responding'. Do not mention mild wheeze here (F-13).
...

Sheet Symptom_Master
A1: symptom_id | B1: symptom | C1: organ_system | D1: wao_table7_grade | E1: criterion1_role | F1: first_state | G1: modality | H1: applies_to | I1: superseded_by | J1: evidence_level | K1: modality_evidence | L1: source | M1: note
A2: SYM-001 | B2: itchy skin | C2: Cutaneous | D2: 1 | E2: skin/mucosal component | F2: early_reaction | G2: subjective | H2: all | J2: Direct | K2: Derived: clinical convention (F-12) | L2: Table 2 (pruritus); Table 7 grade 1
A3: SYM-002 | B3: hives | C3: Cutaneous | D3: 1 | E3: skin/mucosal component | F3: early_reaction | G3: observed | H3: all | J3: Direct | K3: Derived: clinical convention (F-12) | L3: Table 2; Table 7 grade 1 (urticaria)
A4: SYM-003 | B4: flushing | C4: Cutaneous | D4: 1 | E4: skin/mucosal component | F4: early_reaction | G4: observed | H4: all | J4: Direct | K4: Derived: clinical convention (F-12) | L4: Table 2; Table 7 grade 1 (erythema-warmth)
A5: SYM-004 | B5: sense of heat | C5: Cutaneous | D5: not graded | E5: supporting | F5: early_reaction | G5: subjective | H5: all | J5: Direct | K5: Derived: clinical convention (F-12) | L5: p.16 recognition symptoms
A6: SYM-005 | B6: tingling/itching of lips or extremities | C6: Cutaneous | D6: 1 | E6: supporting | F6: early_reaction | G6: subjective | H6: all | J6: Direct | K6: Derived: clinical convention (F-12) | L6: Table 7 grade 1 (lips); p.16 (extremities)
A7: SYM-006 | B7: swollen lips/tongue (non-laryngeal) | C7: Cutaneous | D7: 1 | E7: skin/mucosal component | F7: early_reaction | G7: observed | H7: all | J7: Direct | K7: Derived: clinical convention (F-12) | L7: Table 2; Table 7 grade 1 (angioedema, not laryngeal)
A8: SYM-007 | B8: sneezing, runny or blocked nose | C8: Upper respiratory | D8: 1 | E8: supporting | F8: early_reaction | G8: both | H8: all | J8: Direct | K8: Derived: clinical convention (F-12) | L8: Table 7 grade 1 (nasal symptoms)
A9: SYM-008 | B9: itchy watery eyes | C9: Conjunctival | D9: 1 | E9: supporting | F9: early_reaction | G9: both | H9: all | J9: Direct | K9: Derived: clinical convention (F-12) | L9: Table 7 grade 1
A10: SYM-009 | B10: throat clearing | C10: Upper respiratory | D10: 1 | E10: supporting | F10: early_reaction | G10: both | H10: all | J10: Direct | K10: Derived: clinical convention (F-12) | L10: Table 7 grade 1 (itchy throat)
A11: SYM-010 | B11: cough | C11: Upper respiratory | D11: 1 | E11: supporting | F11: early_reaction | G11: both | H11: all | J11: Direct | K11: Derived: clinical convention (F-12) | L11: Table 7 grade 1 (cough not related to bronchospasm)
A12: SYM-011 | B12: mild wheeze or shortness of breath | C12: Lower respiratory | D12: 3 | E12: qualifier: respiratory compromise | F12: early_reaction | G12: both | H12: all | I12: SYM-022 (marked shortness of breath); SYM-023 (wheeze not improving with treatment) | J12: Direct | K12: Derived: clinical convention (F-12) | L12: Table 2 (a); Table 7 grade 3 (mild bronchospasm, responds to treatment)
A13: SYM-012 | B13: nausea | C13: Gastrointestinal | D13: 1 | E13: supporting | F13: early_reaction | G13: subjective | H13: all | J13: Direct | K13: Derived: clinical convention (F-12) | L13: Table 7 grade 1 (other)
A14: SYM-013 | B14: metallic taste | C14: Gastrointestinal | D14: 1 | E14: supporting | F14: early_reaction | G14: subjective | H14: all | J14: Direct | K14: Derived: clinical convention (F-12) | L14: Table 7 grade 1 (other)
A15: SYM-014 | B15: abdominal cramps | C15: Gastrointestinal | D15: 3 | E15: qualifier: severe GI (only if severe) | F15: early_reaction | G15: subjective | H15: all | J15: Direct | K15: Derived: clinical convention (F-12) | L15: Table 2 (c); Table 7 grade 3
A16: SYM-015 | B16: vomiting or diarrhea | C16: Gastrointestinal | D16: 3 | E16: qualifier: severe GI (only if repetitive) | F16: early_reaction | G16: both | H16: all | J16: Direct | K16: Derived: clinical convention (F-12) | L16: Table 2 (c); Table 7 grade 3
A17: SYM-016 | B17: uterine cramps (female patients) | C17: Other | D17: 3 | E17: supporting | F17: early_reaction | G17: subjective | H17: female patients only | J17: Direct | K17: Derived: clinical convention (F-12) | L17: Table 7 p.13 (grade 3, 'Other')
A18: SYM-017 | B18: dizziness | C18: Neurological/CV | D18: not graded | E18: supporting | F18: early_reaction | G18: subjective | H18: all | J18: Direct | K18: Derived: clinical convention (F-12) | L18: p.16 recognition symptoms
A19: SYM-018 | B19: stridor | C19: Upper airway | D19: 4 | E19: qualifier: respiratory compromise | F19: airway_compromise | G19: observed | H19: all | J19: Direct | K19: Derived: clinical convention (F-12) | L19: Table 2; Table 7 grade 4 (laryngeal edema with stridor)
A20: SYM-019 | B20: hoarse/changed voice | C20: Upper airway | D20: not graded | E20: qualifier: laryngeal involvement | F20: airway_compromise | G20: both | H20: all | J20: Direct | K20: Derived: clinical convention (F-12) | L20: Table 2 footnote c (vocal changes)
A21: SYM-020 | B21: painful swallowing | C21: Upper airway | D21: not graded | E21: qualifier: laryngeal involvement | F21: airway_compromise | G21: subjective | H21: all | J21: Direct | K21: Derived: clinical convention (F-12) | L21: Table 2 footnote c (odynophagia)
A22: SYM-021 | B22: throat or tongue tightness | C22: Upper airway | D22: not graded | E22: supporting | F22: airway_compromise | G22: subjective | H22: all | J22: Derived | K22: Derived: clinical convention (F-12) | L22: Patient-language rendering of laryngeal involvement (F-08)
A23: SYM-022 | B23: marked shortness of breath | C23: Lower respiratory | D23: 4 | E23: qualifier: respiratory compromise | F23: airway_compromise | G23: both | H23: all | J23: Derived | K23: Derived: clinical convention (F-12) | L23: Patient-language rendering of severe bronchospasm, Table 7 grade 4 (F-08)
A24: SYM-023 | B24: wheeze not improving with treatment | C24: Lower respiratory | D24: 4 | E24: qualifier: respiratory compromise | F24: airway_compromise | G24: observed | H24: all | J24: Direct | K24: Derived: clinical convention (F-12) | L24: Table 7 grade 4 (not responding or worsening)
